Workbook

Sheet Resumen Comparativo
A1: CAMARONERA INDUSTRIAL — RESUMEN COMPARATIVO DE ESCENARIOS
A2: Fredy Valladares, Andrea Zambrano
A3: Comparación de métodos de amortización vs escenario sin financiamiento · Horizonte 10 años · Inversión Total: $5,400,000
A4: Método / Escenario | B4: Inversión Total ($) | C4: Financiamiento Bancario ($) | D4: WACC / Tasa de Corte | E4: VAN ($) | F4: TIR (%) | G4: PRI (años) | H4: PRID (años) | I4: ID (Índice Deseabilidad) | J4: Cuota Representativa ($)
A5: Sin Financiamiento | B5: ='Sin Financiamiento'!B77 -> 5400000 | C5: ='Sin Financiamiento'!B102 -> 0 | D5: ='Sin Financiamiento'!E150 -> 0.19 | E5: ='Sin Financiamiento'!B153 -> 3709755.7 | F5: ='Sin Financiamiento'!B154 -> 0.31148854 | G5: ='Sin Financiamiento'!B155 -> 4 | H5: ='Sin Financiamiento'!B156 -> 7 | I5: ='Sin Financiamiento'!B157 -> 1.6869918 | J5: "N/A"
A6: Método Francés (Annuity) | B6: =Francés!B77 -> 5400000 | C6: =Francés!B102 -> 2700000 | D6: =Francés!E150 -> 0.13 | E6: =Francés!B153 -> 7578967.3 | F6: =Francés!B154 -> 0.43681497 | G6: =Francés!B155 -> 4 | H6: =Francés!B156 -> 4 | I6: =Francés!B157 -> 3.8070249 | J6: =Francés!E109 -> 712253.2
A7: Método Americano (Bullet) | B7: =Americano!B77 -> 5400000 | C7: =Americano!B102 -> 2700000 | D7: =Americano!E150 -> 0.13 | E7: =Americano!B153 -> 7720019.7 | F7: =Americano!B154 -> 0.46244432 | G7: =Americano!B155 -> 3 | H7: =Americano!B156 -> 4 | I7: =Americano!B157 -> 3.8592666 | J7: =Americano!C109 -> 270000
A8: Método Italiano (Amort. Constante) | B8: =Italiano!B77 -> 5400000 | C8: =Italiano!B102 -> 2700000 | D8: =Italiano!E150 -> 0.13 | E8: =Italiano!B153 -> 7462388.8 | F8: =Italiano!B154 -> 0.40616532 | G8: =Italiano!B155 -> 4 | H8: =Italiano!B156 -> 5 | I8: =Italiano!B157 -> 3.7638477 | J8: =Italiano!C109 -> 655714.29
A9: Método Alemán (Gradiente) | B9: =Alemán!B77 -> 5400000 | C9: =Alemán!B102 -> 2700000 | D9: =Alemán!E150 -> 0.13 | E9: =Alemán!B153 -> 7412087.8 | F9: =Alemán!B154 -> 0.41162025 | G9: =Alemán!B155 -> 4 | H9: =Alemán!B156 -> 5 | I9: =Alemán!B157 -> 3.4956525 | J9: =Alemán!C109 -> 270000
A10: MEJOR VALOR POR INDICADOR | B10: =MIN(B5:B9) -> 5400000 | C10: =MAX(C5:C9) -> 2700000 | D10: =MIN(D5:D9) -> 0.13 | E10: =MAX(E5:E9) -> 7720019.7 | F10: =MAX(F5:F9) -> 0.46244432 | G10: =MIN(G5:G9) -> 3 | H10: =MIN(H5:H9) -> 4 | I10: =MAX(I5:I9) -> 3.8592666 | J10: =MIN(J5:J9) -> 270000

Sheet Sin Financiamiento
A1: Camaronera Industrial
A3: Variables
A4: Horizonte de evaluación (años) | B4: 10
A5: Devaluación | B5: 0.05
A6: Inflación | B6: 0.07
B7: Año 0 | C7: Año 1 | D7: Año 2 | E7: Año 3 | F7: Año 4 | G7: Año 5 | H7: Año 6 | I7: Año 7 | J7: Año 8 | K7: Año 9 | L7: Año 10
A8: Área en producción (Ha) | C8: 750 | D8: 900 | E8: 900 | F8: 900 | G8: 900 | H8: 900 | I8: 900 | J8: 900 | K8: 900 | L8: 900
A9: Producción neta (Lb/Ha/año) | C9: =1225 -> 1225 | D9: =1470 -> 1470 | E9: =1715 -> 1715 | F9: =1960 -> 1960 | G9: =2205 -> 2205 | H9: =2205 -> 2205 | I9: =2205 -> 2205 | J9: =2205 -> 2205 | K9: =2205 -> 2205 | L9: =2205 -> 2205
A10: Producción neta total (Lb/año) | C10: =C9*C8 -> 918750 | D10: =D9*D8 -> 1323000 | E10: =E9*E8 -> 1543500 | F10: =F9*F8 -> 1764000 | G10: =G9*G8 -> 1984500 | H10: =H9*H8 -> 1984500 | I10: =I9*I8 -> 1984500 | J10: =J9*J8 -> 1984500 | ... L10: =L9*L8 -> 1984500
A11: Tasa de cambio | C11: 1 | D11: =C11+(C11*$B$5) -> 1.05 | E11: =D11+(D11*$B$5) -> 1.1025 | F11: =E11+(E11*$B$5) -> 1.157625 | G11: =F11+(F11*$B$5) -> 1.2155063 | H11: =G11+(G11*$B$5) -> 1.2762816 | I11: =H11+(H11*$B$5) -> 1.3400956 | J11: =I11+(I11*$B$5) -> 1.4071004 | K11: =J11+(J11*$B$5) -> 1.4774554 | L11: =K11+(K11*$B$5) -> 1.5513282
A12: Precio de venta FOB ($/Lb) | C12: 3 | D12: =C12+(C12*$B$6) -> 3.21 | E12: =D12+(D12*$B$6) -> 3.4347 | F12: =E12+(E12*$B$6) -> 3.675129 | G12: =F12+(F12*$B$6) -> 3.932388 | H12: =G12+(G12*$B$6) -> 4.2076552 | I12: =H12+(H12*$B$6) -> 4.5021911 | J12: =I12+(I12*$B$6) -> 4.8173444 | K12: =J12+(J12*$B$6) -> 5.1545585 | L12: =K12+(K12*$B$6) -> 5.5153776
A13: Capital de trabajo | C13: 450000 | D13: 250000 | E13: 250000 | F13: 250000 | G13: 250000 | H13: 250000 | I13: 0 | J13: 0 | K13: 0 | L13: 0
A14: Costos variables ($1.45 x Lb) | C14: =1.45 -> 1.45 | D14: =C14+(C14*$B$6) -> 1.5515 | E14: =D14+(D14*$B$6) -> 1.660105 | F14: =E14+(E14*$B$6) -> 1.7763123 | G14: =F14+(F14*$B$6) -> 1.9006542 | H14: =G14+(G14*$B$6) -> 2.0337 | I14: =H14+(H14*$B$6) -> 2.176059 | J14: =I14+(I14*$B$6) -> 2.3283831 | K14: =J14+(J14*$B$6) -> 2.49137 | L14: =K14+(K14*$B$6) -> 2.6657659
A15: Costos variables anuales | C15: =C14*C10 -> 1332187.5 | D15: =D14*D10 -> 2052634.5 | E15: =E14*E10 -> 2562372.1 | F15: =F14*F10 -> 3133415 | G15: =G14*G10 -> 3771848.3 | H15: =H14*H10 -> 4035877.7 | I15: =I14*I10 -> 4318389.1 | J15: =J14*J10 -> 4620676.3 | ... L15: =L14*L10 -> 5290212.3
A16: Costos fijos de producción | C16: 50000 | D16: =C16+(C16*$B$6) -> 53500 | E16: =D16+(D16*$B$6) -> 57245 | F16: =E16+(E16*$B$6) -> 61252.15 | G16: =F16+(F16*$B$6) -> 65539.8 | H16: =G16+(G16*$B$6) -> 70127.587 | I16: =H16+(H16*$B$6) -> 75036.518 | J16: =I16+(I16*$B$6) -> 80289.074 | K16: =J16+(J16*$B$6) -> 85909.309 | L16: =K16+(K16*$B$6) -> 91922.961
A17: Gastos administrativos | C17: 200000 | D17: =C17+(C17*$B$6) -> 214000 | E17: =D17+(D17*$B$6) -> 228980 | F17: =E17+(E17*$B$6) -> 245008.6 | G17: =F17+(F17*$B$6) -> 262159.2 | H17: =G17+(G17*$B$6) -> 280510.35 | I17: =H17+(H17*$B$6) -> 300146.07 | J17: =I17+(I17*$B$6) -> 321156.3 | K17: =J17+(J17*$B$6) -> 343637.24 | L17: =K17+(K17*$B$6) -> 367691.84
A19: Valor residual del terreno | B19: 1250000
A20: Valor residual de estanques y canales | B20: 1000000
A21: Valor residual de edificios | B21: 50000
A22: Tasa de fiananciamiento bancario | B22: 0.1
A23: Plazo del financiamiento bancario (años) | B23: 7
A24: Plazo del financiamiento bancario (valor) | B24: =5400000*0.5 -> 2700000
A25: Tasa de corte | B25: 0.19
A26: Tasa de ISR | B26: 0.3
A28: 1. Ingresos del proyecto
A29: Calendario de ingresos (venta del producto)
A30: Concepto | B30: Año 0 | C30: Año 1 | D30: Año 2 | E30: Año 3 | F30: Año 4 | G30: Año 5 | H30: Año 6 | I30: Año 7 | J30: Año 8 | K30: Año 9 | L30: Año 10
A31: Cantidad de camarón (Lb) | C31: =C10 -> 918750 | D31: =D10 -> 1323000 | E31: =E10 -> 1543500 | F31: =F10 -> 1764000 | G31: =G10 -> 1984500 | H31: =H10 -> 1984500 | I31: =I10 -> 1984500 | J31: =J10 -> 1984500 | ... L31: =L10 -> 1984500
A32: Precio unitario de venta ($/Lb) | C32: =C12 -> 3 | D32: =D12 -> 3.21 | E32: =E12 -> 3.4347 | F32: =F12 -> 3.675129 | G32: =G12 -> 3.932388 | H32: =H12 -> 4.2076552 | I32: =I12 -> 4.5021911 | J32: =J12 -> 4.8173444 | ... L32: =L12 -> 5.5153776
A33: Ingresos | C33: =C32*C31 -> 2756250 | D33: =D32*D31 -> 4246830 | E33: =E32*E31 -> 5301459.5 | F33: =F32*F31 -> 6482927.6 | G33: =G32*G31 -> 7803824 | H33: =H32*H31 -> 8350091.7 | I33: =I32*I31 -> 8934598.1 | J33: =J32*J31 -> 9560020 | ... L33: =L32*L31 -> 10945267
A35: 2. Costos variables
A36: Calendario de costos variables
A37: Concepto | B37: Año 0 | C37: Año 1 | D37: Año 2 | E37: Año 3 | F37: Año 4 | G37: Año 5 | H37: Año 6 | I37: Año 7 | J37: Año 8 | K37: Año 9 | L37: Año 10
A38: Costos variables | C38: =C15 -> 1332187.5 | D38: =D15 -> 2052634.5 | E38: =E15 -> 2562372.1 | F38: =F15 -> 3133415 | G38: =G15 -> 3771848.3 | H38: =H15 -> 4035877.7 | I38: =I15 -> 4318389.1 | J38: =J15 -> 4620676.3 | ... L38: =L15 -> 5290212.3
A39: Total de costos variables | C39: =C38 -> 1332187.5 | D39: =D38 -> 2052634.5 | E39: =E38 -> 2562372.1 | F39: =F38 -> 3133415 | G39: =G38 -> 3771848.3 | H39: =H38 -> 4035877.7 | I39: =I38 -> 4318389.1 | J39: =J38 -> 4620676.3 | ... L39: =L38 -> 5290212.3
A41: 3. Costos fijos
A42: Calendario de los costos fijos
A43: Concepto | B43: Año 0 | C43: Año 1 | D43: Año 2 | E43: Año 3 | F43: Año 4 | G43: Año 5 | H43: Año 6 | I43: Año 7 | J43: Año 8 | K43: Año 9 | L43: Año 10
A44: Costos fijos de producción | C44: =C16 -> 50000 | D44: =D16 -> 53500 | E44: =E16 -> 57245 | F44: =F16 -> 61252.15 | G44: =G16 -> 65539.8 | H44: =H16 -> 70127.587 | I44: =I16 -> 75036.518 | J44: =J16 -> 80289.074 | ... L44: =L16 -> 91922.961
A45: Gastos administrativos | C45: =C17 -> 200000 | D45: =D17 -> 214000 | E45: =E17 -> 228980 | F45: =F17 -> 245008.6 | G45: =G17 -> 262159.2 | H45: =H17 -> 280510.35 | I45: =I17 -> 300146.07 | J45: =J17 -> 321156.3 | ... L45: =L17 -> 367691.84
...

Sheet PE$ sin Financiamiento
A1: Camaronera Industrial
A3: Variables
A4: Horizonte de evaluación (años) | B4: 10
A5: Devaluación | B5: 0.05
A6: Inflación | B6: 0.07
B7: Año 0 | C7: Año 1 | D7: Año 2 | E7: Año 3 | F7: Año 4 | G7: Año 5 | H7: Año 6 | I7: Año 7 | J7: Año 8 | K7: Año 9 | L7: Año 10
A8: Área en producción (Ha) | C8: 750 | D8: 900 | E8: 900 | F8: 900 | G8: 900 | H8: 900 | I8: 900 | J8: 900 | K8: 900 | L8: 900
A9: Producción neta (Lb/Ha/año) | C9: =1225 -> 1225 | D9: =1470 -> 1470 | E9: =1715 -> 1715 | F9: =1960 -> 1960 | G9: =2205 -> 2205 | H9: =2205 -> 2205 | I9: =2205 -> 2205 | J9: =2205 -> 2205 | K9: =2205 -> 2205 | L9: =2205 -> 2205
A10: Producción neta total (Lb/año) | C10: =C9*C8 -> 918750 | D10: =D9*D8 -> 1323000 | E10: =E9*E8 -> 1543500 | F10: =F9*F8 -> 1764000 | G10: =G9*G8 -> 1984500 | H10: =H9*H8 -> 1984500 | I10: =I9*I8 -> 1984500 | J10: =J9*J8 -> 1984500 | ... L10: =L9*L8 -> 1984500
A11: Tasa de cambio | C11: 1 | D11: =C11+(C11*$B$5) -> 1.05 | E11: =D11+(D11*$B$5) -> 1.1025 | F11: =E11+(E11*$B$5) -> 1.157625 | G11: =F11+(F11*$B$5) -> 1.2155063 | H11: =G11+(G11*$B$5) -> 1.2762816 | I11: =H11+(H11*$B$5) -> 1.3400956 | J11: =I11+(I11*$B$5) -> 1.4071004 | K11: =J11+(J11*$B$5) -> 1.4774554 | L11: =K11+(K11*$B$5) -> 1.5513282
A12: Precio de venta FOB ($/Lb) | C12: 2.4108299 | D12: =C12+(C12*$B$6) -> 2.579588 | E12: =D12+(D12*$B$6) -> 2.7601592 | F12: =E12+(E12*$B$6) -> 2.9533703 | G12: =F12+(F12*$B$6) -> 3.1601062 | H12: =G12+(G12*$B$6) -> 3.3813137 | I12: =H12+(H12*$B$6) -> 3.6180056 | J12: =I12+(I12*$B$6) -> 3.871266 | K12: =J12+(J12*$B$6) -> 4.1422546 | L12: =K12+(K12*$B$6) -> 4.4322124
A13: Capital de trabajo | C13: 450000 | D13: 250000 | E13: 250000 | F13: 250000 | G13: 250000 | H13: 250000 | I13: 0 | J13: 0 | K13: 0 | L13: 0
A14: Costos variables ($1.45 x Lb) | C14: =1.45 -> 1.45 | D14: =C14+(C14*$B$6) -> 1.5515 | E14: =D14+(D14*$B$6) -> 1.660105 | F14: =E14+(E14*$B$6) -> 1.7763123 | G14: =F14+(F14*$B$6) -> 1.9006542 | H14: =G14+(G14*$B$6) -> 2.0337 | I14: =H14+(H14*$B$6) -> 2.176059 | J14: =I14+(I14*$B$6) -> 2.3283831 | K14: =J14+(J14*$B$6) -> 2.49137 | L14: =K14+(K14*$B$6) -> 2.6657659
A15: Costos variables anuales | C15: =C14*C10 -> 1332187.5 | D15: =D14*D10 -> 2052634.5 | E15: =E14*E10 -> 2562372.1 | F15: =F14*F10 -> 3133415 | G15: =G14*G10 -> 3771848.3 | H15: =H14*H10 -> 4035877.7 | I15: =I14*I10 -> 4318389.1 | J15: =J14*J10 -> 4620676.3 | ... L15: =L14*L10 -> 5290212.3
A16: Costos fijos de producción | C16: 50000 | D16: =C16+(C16*$B$6) -> 53500 | E16: =D16+(D16*$B$6) -> 57245 | F16: =E16+(E16*$B$6) -> 61252.15 | G16: =F16+(F16*$B$6) -> 65539.8 | H16: =G16+(G16*$B$6) -> 70127.587 | I16: =H16+(H16*$B$6) -> 75036.518 | J16: =I16+(I16*$B$6) -> 80289.074 | K16: =J16+(J16*$B$6) -> 85909.309 | L16: =K16+(K16*$B$6) -> 91922.961
A17: Gastos administrativos | C17: 200000 | D17: =C17+(C17*$B$6) -> 214000 | E17: =D17+(D17*$B$6) -> 228980 | F17: =E17+(E17*$B$6) -> 245008.6 | G17: =F17+(F17*$B$6) -> 262159.2 | H17: =G17+(G17*$B$6) -> 280510.35 | I17: =H17+(H17*$B$6) -> 300146.07 | J17: =I17+(I17*$B$6) -> 321156.3 | K17: =J17+(J17*$B$6) -> 343637.24 | L17: =K17+(K17*$B$6) -> 367691.84
A19: Valor residual del terreno | B19: 1250000
A20: Valor residual de estanques y canales | B20: 1000000
A21: Valor residual de edificios | B21: 50000
A22: Tasa de fiananciamiento bancario | B22: 0.1
A23: Plazo del financiamiento bancario (años) | B23: 7
A24: Plazo del financiamiento bancario (valor) | B24: =5400000*0.5 -> 2700000
A25: Tasa de corte | B25: 0.19
A26: Tasa de ISR | B26: 0.3
A28: 1. Ingresos del proyecto
A29: Calendario de ingresos (venta del producto)
A30: Concepto | B30: Año 0 | C30: Año 1 | D30: Año 2 | E30: Año 3 | F30: Año 4 | G30: Año 5 | H30: Año 6 | I30: Año 7 | J30: Año 8 | K30: Año 9 | L30: Año 10
A31: Cantidad de camarón (Lb) | C31: =C10 -> 918750 | D31: =D10 -> 1323000 | E31: =E10 -> 1543500 | F31: =F10 -> 1764000 | G31: =G10 -> 1984500 | H31: =H10 -> 1984500 | I31: =I10 -> 1984500 | J31: =J10 -> 1984500 | ... L31: =L10 -> 1984500
A32: Precio unitario de venta ($/Lb) | C32: =C12 -> 2.4108299 | D32: =D12 -> 2.579588 | E32: =E12 -> 2.7601592 | F32: =F12 -> 2.9533703 | G32: =G12 -> 3.1601062 | H32: =H12 -> 3.3813137 | I32: =I12 -> 3.6180056 | J32: =J12 -> 3.871266 | ... L32: =L12 -> 4.4322124
A33: Ingresos | C33: =C32*C31 -> 2214950 | D33: =D32*D31 -> 3412794.9 | E33: =E32*E31 -> 4260305.7 | F33: =F32*F31 -> 5209745.2 | G33: =G32*G31 -> 6271230.8 | H33: =H32*H31 -> 6710216.9 | I33: =I32*I31 -> 7179932.1 | J33: =J32*J31 -> 7682527.4 | ... L33: =L32*L31 -> 8795725.6
A35: 2. Costos variables
A36: Calendario de costos variables
A37: Concepto | B37: Año 0 | C37: Año 1 | D37: Año 2 | E37: Año 3 | F37: Año 4 | G37: Año 5 | H37: Año 6 | I37: Año 7 | J37: Año 8 | K37: Año 9 | L37: Año 10
A38: Costos variables | C38: =C15 -> 1332187.5 | D38: =D15 -> 2052634.5 | E38: =E15 -> 2562372.1 | F38: =F15 -> 3133415 | G38: =G15 -> 3771848.3 | H38: =H15 -> 4035877.7 | I38: =I15 -> 4318389.1 | J38: =J15 -> 4620676.3 | ... L38: =L15 -> 5290212.3
A39: Total de costos variables | C39: =C38 -> 1332187.5 | D39: =D38 -> 2052634.5 | E39: =E38 -> 2562372.1 | F39: =F38 -> 3133415 | G39: =G38 -> 3771848.3 | H39: =H38 -> 4035877.7 | I39: =I38 -> 4318389.1 | J39: =J38 -> 4620676.3 | ... L39: =L38 -> 5290212.3
A41: 3. Costos fijos
A42: Calendario de los costos fijos
A43: Concepto | B43: Año 0 | C43: Año 1 | D43: Año 2 | E43: Año 3 | F43: Año 4 | G43: Año 5 | H43: Año 6 | I43: Año 7 | J43: Año 8 | K43: Año 9 | L43: Año 10
A44: Costos fijos de producción | C44: =C16 -> 50000 | D44: =D16 -> 53500 | E44: =E16 -> 57245 | F44: =F16 -> 61252.15 | G44: =G16 -> 65539.8 | H44: =H16 -> 70127.587 | I44: =I16 -> 75036.518 | J44: =J16 -> 80289.074 | ... L44: =L16 -> 91922.961
A45: Gastos administrativos | C45: =C17 -> 200000 | D45: =D17 -> 214000 | E45: =E17 -> 228980 | F45: =F17 -> 245008.6 | G45: =G17 -> 262159.2 | H45: =H17 -> 280510.35 | I45: =I17 -> 300146.07 | J45: =J17 -> 321156.3 | ... L45: =L17 -> 367691.84
...

Sheet PEx sin Financiamiento
A1: Camaronera Industrial
A3: Variables
A4: Horizonte de evaluación (años) | B4: 10
A5: Devaluación | B5: 0.05
A6: Inflación | B6: 0.07
B7: Año 0 | C7: Año 1 | D7: Año 2 | E7: Año 3 | F7: Año 4 | G7: Año 5 | H7: Año 6 | I7: Año 7 | J7: Año 8 | K7: Año 9 | L7: Año 10
A8: Área en producción (Ha) | C8: 750 | D8: 900 | E8: 900 | F8: 900 | G8: 900 | H8: 900 | I8: 900 | J8: 900 | K8: 900 | L8: 900
A9: Producción neta (Lb/Ha/año) | C9: =1225 -> 1225 | D9: =1470 -> 1470 | E9: =1715 -> 1715 | F9: =1960 -> 1960 | G9: =2205 -> 2205 | H9: =2205 -> 2205 | I9: =2205 -> 2205 | J9: =2205 -> 2205 | K9: =2205 -> 2205 | L9: =2205 -> 2205
A10: Producción neta total (Lb/año) | C10: =C9*C8 -> 918750 | D10: =D9*D8 -> 1323000 | E10: =E9*E8 -> 1543500 | F10: =F9*F8 -> 1764000 | G10: =G9*G8 -> 1984500 | H10: =H9*H8 -> 1984500 | I10: =I9*I8 -> 1984500 | J10: =J9*J8 -> 1984500 | ... L10: =L9*L8 -> 1984500
A11: Tasa de cambio | C11: 1 | D11: =C11+(C11*$B$5) -> 1.05 | E11: =D11+(D11*$B$5) -> 1.1025 | F11: =E11+(E11*$B$5) -> 1.157625 | G11: =F11+(F11*$B$5) -> 1.2155063 | H11: =G11+(G11*$B$5) -> 1.2762816 | I11: =H11+(H11*$B$5) -> 1.3400956 | J11: =I11+(I11*$B$5) -> 1.4071004 | K11: =J11+(J11*$B$5) -> 1.4774554 | L11: =K11+(K11*$B$5) -> 1.5513282
A12: Precio de venta FOB ($/Lb) | C12: 3 | D12: =C12+(C12*$B$6) -> 3.21 | E12: =D12+(D12*$B$6) -> 3.4347 | F12: =E12+(E12*$B$6) -> 3.675129 | G12: =F12+(F12*$B$6) -> 3.932388 | H12: =G12+(G12*$B$6) -> 4.2076552 | I12: =H12+(H12*$B$6) -> 4.5021911 | J12: =I12+(I12*$B$6) -> 4.8173444 | K12: =J12+(J12*$B$6) -> 5.1545585 | L12: =K12+(K12*$B$6) -> 5.5153776
A13: Capital de trabajo | C13: 450000 | D13: 250000 | E13: 250000 | F13: 250000 | G13: 250000 | H13: 250000 | I13: 0 | J13: 0 | K13: 0 | L13: 0
A14: Costos variables ($1.45 x Lb) | C14: =1.45 -> 1.45 | D14: =C14+(C14*$B$6) -> 1.5515 | E14: =D14+(D14*$B$6) -> 1.660105 | F14: =E14+(E14*$B$6) -> 1.7763123 | G14: =F14+(F14*$B$6) -> 1.9006542 | H14: =G14+(G14*$B$6) -> 2.0337 | I14: =H14+(H14*$B$6) -> 2.176059 | J14: =I14+(I14*$B$6) -> 2.3283831 | K14: =J14+(J14*$B$6) -> 2.49137 | L14: =K14+(K14*$B$6) -> 2.6657659
A15: Costos variables anuales | C15: =C14*C10 -> 1332187.5 | D15: =D14*D10 -> 2052634.5 | E15: =E14*E10 -> 2562372.1 | F15: =F14*F10 -> 3133415 | G15: =G14*G10 -> 3771848.3 | H15: =H14*H10 -> 4035877.7 | I15: =I14*I10 -> 4318389.1 | J15: =J14*J10 -> 4620676.3 | ... L15: =L14*L10 -> 5290212.3
A16: Costos fijos de producción | C16: 50000 | D16: =C16+(C16*$B$6) -> 53500 | E16: =D16+(D16*$B$6) -> 57245 | F16: =E16+(E16*$B$6) -> 61252.15 | G16: =F16+(F16*$B$6) -> 65539.8 | H16: =G16+(G16*$B$6) -> 70127.587 | I16: =H16+(H16*$B$6) -> 75036.518 | J16: =I16+(I16*$B$6) -> 80289.074 | K16: =J16+(J16*$B$6) -> 85909.309 | L16: =K16+(K16*$B$6) -> 91922.961
A17: Gastos administrativos | C17: 200000 | D17: =C17+(C17*$B$6) -> 214000 | E17: =D17+(D17*$B$6) -> 228980 | F17: =E17+(E17*$B$6) -> 245008.6 | G17: =F17+(F17*$B$6) -> 262159.2 | H17: =G17+(G17*$B$6) -> 280510.35 | I17: =H17+(H17*$B$6) -> 300146.07 | J17: =I17+(I17*$B$6) -> 321156.3 | K17: =J17+(J17*$B$6) -> 343637.24 | L17: =K17+(K17*$B$6) -> 367691.84
A19: Valor residual del terreno | B19: 1250000
A20: Valor residual de estanques y canales | B20: 1000000
A21: Valor residual de edificios | B21: 50000
A22: Tasa de fiananciamiento bancario | B22: 0.1
A23: Plazo del financiamiento bancario (años) | B23: 7
A24: Plazo del financiamiento bancario (valor) | B24: =5400000*0.5 -> 2700000
A25: Tasa de corte | B25: 0.19
A26: Tasa de ISR | B26: 0.3
D27: 0.44 | E27: 0.16666667 | F27: 0.14285714 | G27: 0.125 | H27: 0 | I27: 0 | J27: 0 | K27: 0 | L27: 0
A28: 1. Ingresos del proyecto | C28: 918750 | D28: 1323000 | E28: 1543500 | F28: 1764000 | G28: 1984500 | H28: 1984500 | I28: 1984500 | J28: 1984500 | K28: 1984500 | L28: 1984500
A29: Calendario de ingresos (venta del producto)
A30: Concepto | B30: Año 0 | C30: Año 1 | D30: Año 2 | E30: Año 3 | F30: Año 4 | G30: Año 5 | H30: Año 6 | I30: Año 7 | J30: Año 8 | K30: Año 9 | L30: Año 10
A31: Cantidad de camarón (Lb) | C31: 738316.66 | D31: =C31+(C31*D27) -> 1063176 | E31: =D31+(D31*E27) -> 1240372 | F31: =E31+(E31*F27) -> 1417568 | G31: =F31+(F31*G27) -> 1594764 | H31: =G31+(G31*H27) -> 1594764 | I31: =H31+(H31*I27) -> 1594764 | J31: =I31+(I31*J27) -> 1594764 | K31: =J31+(J31*K27) -> 1594764 | L31: =K31+(K31*L27) -> 1594764
A32: Precio unitario de venta ($/Lb) | C32: =C12 -> 3 | D32: =D12 -> 3.21 | E32: =E12 -> 3.4347 | F32: =F12 -> 3.675129 | G32: =G12 -> 3.932388 | H32: =H12 -> 4.2076552 | I32: =I12 -> 4.5021911 | J32: =J12 -> 4.8173444 | ... L32: =L12 -> 5.5153776
A33: Ingresos | C33: =C32*C31 -> 2214950 | D33: =D32*D31 -> 3412794.9 | E33: =E32*E31 -> 4260305.7 | F33: =F32*F31 -> 5209745.2 | G33: =G32*G31 -> 6271230.8 | H33: =H32*H31 -> 6710216.9 | I33: =I32*I31 -> 7179932.1 | J33: =J32*J31 -> 7682527.4 | ... L33: =L32*L31 -> 8795725.6
A35: 2. Costos variables
A36: Calendario de costos variables
A37: Concepto | B37: Año 0 | C37: Año 1 | D37: Año 2 | E37: Año 3 | F37: Año 4 | G37: Año 5 | H37: Año 6 | I37: Año 7 | J37: Año 8 | K37: Año 9 | L37: Año 10
A38: Costos variables | C38: =C15 -> 1332187.5 | D38: =D15 -> 2052634.5 | E38: =E15 -> 2562372.1 | F38: =F15 -> 3133415 | G38: =G15 -> 3771848.3 | H38: =H15 -> 4035877.7 | I38: =I15 -> 4318389.1 | J38: =J15 -> 4620676.3 | ... L38: =L15 -> 5290212.3
A39: Total de costos variables | C39: =C38 -> 1332187.5 | D39: =D38 -> 2052634.5 | E39: =E38 -> 2562372.1 | F39: =F38 -> 3133415 | G39: =G38 -> 3771848.3 | H39: =H38 -> 4035877.7 | I39: =I38 -> 4318389.1 | J39: =J38 -> 4620676.3 | ... L39: =L38 -> 5290212.3
A41: 3. Costos fijos
A42: Calendario de los costos fijos
A43: Concepto | B43: Año 0 | C43: Año 1 | D43: Año 2 | E43: Año 3 | F43: Año 4 | G43: Año 5 | H43: Año 6 | I43: Año 7 | J43: Año 8 | K43: Año 9 | L43: Año 10
A44: Costos fijos de producción | C44: =C16 -> 50000 | D44: =D16 -> 53500 | E44: =E16 -> 57245 | F44: =F16 -> 61252.15 | G44: =G16 -> 65539.8 | H44: =H16 -> 70127.587 | I44: =I16 -> 75036.518 | J44: =J16 -> 80289.074 | ... L44: =L16 -> 91922.961
...

Sheet Francés
A1: Camaronera Industrial
A3: Variables
A4: Horizonte de evaluación (años) | B4: 10
A5: Devaluación | B5: 0.05
A6: Inflación | B6: 0.07
B7: Año 0 | C7: Año 1 | D7: Año 2 | E7: Año 3 | F7: Año 4 | G7: Año 5 | H7: Año 6 | I7: Año 7 | J7: Año 8 | K7: Año 9 | L7: Año 10
A8: Área en producción (Ha) | C8: 750 | D8: 900 | E8: 900 | F8: 900 | G8: 900 | H8: 900 | I8: 900 | J8: 900 | K8: 900 | L8: 900
A9: Producción neta (Lb/Ha/año) | C9: =1225 -> 1225 | D9: =1470 -> 1470 | E9: =1715 -> 1715 | F9: =1960 -> 1960 | G9: =2205 -> 2205 | H9: =2205 -> 2205 | I9: =2205 -> 2205 | J9: =2205 -> 2205 | K9: =2205 -> 2205 | L9: =2205 -> 2205
A10: Producción neta total (Lb/año) | C10: =C9*C8 -> 918750 | D10: =D9*D8 -> 1323000 | E10: =E9*E8 -> 1543500 | F10: =F9*F8 -> 1764000 | G10: =G9*G8 -> 1984500 | H10: =H9*H8 -> 1984500 | I10: =I9*I8 -> 1984500 | J10: =J9*J8 -> 1984500 | ... L10: =L9*L8 -> 1984500
A11: Tasa de cambio | C11: 1 | D11: =C11+(C11*$B$5) -> 1.05 | E11: =D11+(D11*$B$5) -> 1.1025 | F11: =E11+(E11*$B$5) -> 1.157625 | G11: =F11+(F11*$B$5) -> 1.2155063 | H11: =G11+(G11*$B$5) -> 1.2762816 | I11: =H11+(H11*$B$5) -> 1.3400956 | J11: =I11+(I11*$B$5) -> 1.4071004 | K11: =J11+(J11*$B$5) -> 1.4774554 | L11: =K11+(K11*$B$5) -> 1.5513282
A12: Precio de venta FOB ($/Lb) | C12: 3 | D12: =C12+(C12*$B$6) -> 3.21 | E12: =D12+(D12*$B$6) -> 3.4347 | F12: =E12+(E12*$B$6) -> 3.675129 | G12: =F12+(F12*$B$6) -> 3.932388 | H12: =G12+(G12*$B$6) -> 4.2076552 | I12: =H12+(H12*$B$6) -> 4.5021911 | J12: =I12+(I12*$B$6) -> 4.8173444 | K12: =J12+(J12*$B$6) -> 5.1545585 | L12: =K12+(K12*$B$6) -> 5.5153776
A13: Capital de trabajo | C13: 450000 | D13: 250000 | E13: 250000 | F13: 250000 | G13: 250000 | H13: 250000 | I13: 0 | J13: 0 | K13: 0 | L13: 0
A14: Costos variables ($1.45 x Lb) | C14: =1.45 -> 1.45 | D14: =C14+(C14*$B$6) -> 1.5515 | E14: =D14+(D14*$B$6) -> 1.660105 | F14: =E14+(E14*$B$6) -> 1.7763123 | G14: =F14+(F14*$B$6) -> 1.9006542 | H14: =G14+(G14*$B$6) -> 2.0337 | I14: =H14+(H14*$B$6) -> 2.176059 | J14: =I14+(I14*$B$6) -> 2.3283831 | K14: =J14+(J14*$B$6) -> 2.49137 | L14: =K14+(K14*$B$6) -> 2.6657659
A15: Costos variables anuales | C15: =C14*C10 -> 1332187.5 | D15: =D14*D10 -> 2052634.5 | E15: =E14*E10 -> 2562372.1 | F15: =F14*F10 -> 3133415 | G15: =G14*G10 -> 3771848.3 | H15: =H14*H10 -> 4035877.7 | I15: =I14*I10 -> 4318389.1 | J15: =J14*J10 -> 4620676.3 | ... L15: =L14*L10 -> 5290212.3
A16: Costos fijos de producción | C16: 50000 | D16: =C16+(C16*$B$6) -> 53500 | E16: =D16+(D16*$B$6) -> 57245 | F16: =E16+(E16*$B$6) -> 61252.15 | G16: =F16+(F16*$B$6) -> 65539.8 | H16: =G16+(G16*$B$6) -> 70127.587 | I16: =H16+(H16*$B$6) -> 75036.518 | J16: =I16+(I16*$B$6) -> 80289.074 | K16: =J16+(J16*$B$6) -> 85909.309 | L16: =K16+(K16*$B$6) -> 91922.961
A17: Gastos administrativos | C17: 200000 | D17: =C17+(C17*$B$6) -> 214000 | E17: =D17+(D17*$B$6) -> 228980 | F17: =E17+(E17*$B$6) -> 245008.6 | G17: =F17+(F17*$B$6) -> 262159.2 | H17: =G17+(G17*$B$6) -> 280510.35 | I17: =H17+(H17*$B$6) -> 300146.07 | J17: =I17+(I17*$B$6) -> 321156.3 | K17: =J17+(J17*$B$6) -> 343637.24 | L17: =K17+(K17*$B$6) -> 367691.84
A19: Valor residual del terreno | B19: 1250000
A20: Valor residual de estanques y canales | B20: 1000000
A21: Valor residual de edificios | B21: 50000
A22: Tasa de fiananciamiento bancario | B22: 0.1
A23: Plazo del financiamiento bancario (años) | B23: 7
A24: Plazo del financiamiento bancario (valor) | B24: =5400000*0.5 -> 2700000
A25: Tasa de corte | B25: 0.19
A26: Tasa de ISR | B26: 0.3
A28: 1. Ingresos del proyecto
A29: Calendario de ingresos (venta del producto)
A30: Concepto | B30: Año 0 | C30: Año 1 | D30: Año 2 | E30: Año 3 | F30: Año 4 | G30: Año 5 | H30: Año 6 | I30: Año 7 | J30: Año 8 | K30: Año 9 | L30: Año 10
A31: Cantidad de camarón (Lb) | C31: =C10 -> 918750 | D31: =D10 -> 1323000 | E31: =E10 -> 1543500 | F31: =F10 -> 1764000 | G31: =G10 -> 1984500 | H31: =H10 -> 1984500 | I31: =I10 -> 1984500 | J31: =J10 -> 1984500 | ... L31: =L10 -> 1984500
A32: Precio unitario de venta ($/Lb) | C32: =C12 -> 3 | D32: =D12 -> 3.21 | E32: =E12 -> 3.4347 | F32: =F12 -> 3.675129 | G32: =G12 -> 3.932388 | H32: =H12 -> 4.2076552 | I32: =I12 -> 4.5021911 | J32: =J12 -> 4.8173444 | ... L32: =L12 -> 5.5153776
A33: Ingresos | C33: =C32*C31 -> 2756250 | D33: =D32*D31 -> 4246830 | E33: =E32*E31 -> 5301459.5 | F33: =F32*F31 -> 6482927.6 | G33: =G32*G31 -> 7803824 | H33: =H32*H31 -> 8350091.7 | I33: =I32*I31 -> 8934598.1 | J33: =J32*J31 -> 9560020 | ... L33: =L32*L31 -> 10945267
A35: 2. Costos variables
A36: Calendario de costos variables
A37: Concepto | B37: Año 0 | C37: Año 1 | D37: Año 2 | E37: Año 3 | F37: Año 4 | G37: Año 5 | H37: Año 6 | I37: Año 7 | J37: Año 8 | K37: Año 9 | L37: Año 10
A38: Costos variables | C38: =C15 -> 1332187.5 | D38: =D15 -> 2052634.5 | E38: =E15 -> 2562372.1 | F38: =F15 -> 3133415 | G38: =G15 -> 3771848.3 | H38: =H15 -> 4035877.7 | I38: =I15 -> 4318389.1 | J38: =J15 -> 4620676.3 | ... L38: =L15 -> 5290212.3
A39: Total de costos variables | C39: =C38 -> 1332187.5 | D39: =D38 -> 2052634.5 | E39: =E38 -> 2562372.1 | F39: =F38 -> 3133415 | G39: =G38 -> 3771848.3 | H39: =H38 -> 4035877.7 | I39: =I38 -> 4318389.1 | J39: =J38 -> 4620676.3 | ... L39: =L38 -> 5290212.3
A41: 3. Costos fijos
A42: Calendario de los costos fijos
A43: Concepto | B43: Año 0 | C43: Año 1 | D43: Año 2 | E43: Año 3 | F43: Año 4 | G43: Año 5 | H43: Año 6 | I43: Año 7 | J43: Año 8 | K43: Año 9 | L43: Año 10
A44: Costos fijos de producción | C44: =C16 -> 50000 | D44: =D16 -> 53500 | E44: =E16 -> 57245 | F44: =F16 -> 61252.15 | G44: =G16 -> 65539.8 | H44: =H16 -> 70127.587 | I44: =I16 -> 75036.518 | J44: =J16 -> 80289.074 | ... L44: =L16 -> 91922.961
A45: Gastos administrativos | C45: =C17 -> 200000 | D45: =D17 -> 214000 | E45: =E17 -> 228980 | F45: =F17 -> 245008.6 | G45: =G17 -> 262159.2 | H45: =H17 -> 280510.35 | I45: =I17 -> 300146.07 | J45: =J17 -> 321156.3 | ... L45: =L17 -> 367691.84
...

Sheet Americano
A1: Camaronera Industrial
A3: Variables
A4: Horizonte de evaluación (años) | B4: 10
A5: Devaluación | B5: 0.05
A6: Inflación | B6: 0.07
B7: Año 0 | C7: Año 1 | D7: Año 2 | E7: Año 3 | F7: Año 4 | G7: Año 5 | H7: Año 6 | I7: Año 7 | J7: Año 8 | K7: Año 9 | L7: Año 10
A8: Área en producción (Ha) | C8: 750 | D8: 900 | E8: 900 | F8: 900 | G8: 900 | H8: 900 | I8: 900 | J8: 900 | K8: 900 | L8: 900
A9: Producción neta (Lb/Ha/año) | C9: =1225 -> 1225 | D9: =1470 -> 1470 | E9: =1715 -> 1715 | F9: =1960 -> 1960 | G9: =2205 -> 2205 | H9: =2205 -> 2205 | I9: =2205 -> 2205 | J9: =2205 -> 2205 | K9: =2205 -> 2205 | L9: =2205 -> 2205
A10: Producción neta total (Lb/año) | C10: =C9*C8 -> 918750 | D10: =D9*D8 -> 1323000 | E10: =E9*E8 -> 1543500 | F10: =F9*F8 -> 1764000 | G10: =G9*G8 -> 1984500 | H10: =H9*H8 -> 1984500 | I10: =I9*I8 -> 1984500 | J10: =J9*J8 -> 1984500 | ... L10: =L9*L8 -> 1984500
A11: Tasa de cambio | C11: 1 | D11: =C11+(C11*$B$5) -> 1.05 | E11: =D11+(D11*$B$5) -> 1.1025 | F11: =E11+(E11*$B$5) -> 1.157625 | G11: =F11+(F11*$B$5) -> 1.2155063 | H11: =G11+(G11*$B$5) -> 1.2762816 | I11: =H11+(H11*$B$5) -> 1.3400956 | J11: =I11+(I11*$B$5) -> 1.4071004 | K11: =J11+(J11*$B$5) -> 1.4774554 | L11: =K11+(K11*$B$5) -> 1.5513282
A12: Precio de venta FOB ($/Lb) | C12: 3 | D12: =C12+(C12*$B$6) -> 3.21 | E12: =D12+(D12*$B$6) -> 3.4347 | F12: =E12+(E12*$B$6) -> 3.675129 | G12: =F12+(F12*$B$6) -> 3.932388 | H12: =G12+(G12*$B$6) -> 4.2076552 | I12: =H12+(H12*$B$6) -> 4.5021911 | J12: =I12+(I12*$B$6) -> 4.8173444 | K12: =J12+(J12*$B$6) -> 5.1545585 | L12: =K12+(K12*$B$6) -> 5.5153776
A13: Capital de trabajo | C13: 450000 | D13: 250000 | E13: 250000 | F13: 250000 | G13: 250000 | H13: 250000 | I13: 0 | J13: 0 | K13: 0 | L13: 0
A14: Costos variables ($1.45 x Lb) | C14: =1.45 -> 1.45 | D14: =C14+(C14*$B$6) -> 1.5515 | E14: =D14+(D14*$B$6) -> 1.660105 | F14: =E14+(E14*$B$6) -> 1.7763123 | G14: =F14+(F14*$B$6) -> 1.9006542 | H14: =G14+(G14*$B$6) -> 2.0337 | I14: =H14+(H14*$B$6) -> 2.176059 | J14: =I14+(I14*$B$6) -> 2.3283831 | K14: =J14+(J14*$B$6) -> 2.49137 | L14: =K14+(K14*$B$6) -> 2.6657659
A15: Costos variables anuales | C15: =C14*C10 -> 1332187.5 | D15: =D14*D10 -> 2052634.5 | E15: =E14*E10 -> 2562372.1 | F15: =F14*F10 -> 3133415 | G15: =G14*G10 -> 3771848.3 | H15: =H14*H10 -> 4035877.7 | I15: =I14*I10 -> 4318389.1 | J15: =J14*J10 -> 4620676.3 | ... L15: =L14*L10 -> 5290212.3
A16: Costos fijos de producción | C16: 50000 | D16: =C16+(C16*$B$6) -> 53500 | E16: =D16+(D16*$B$6) -> 57245 | F16: =E16+(E16*$B$6) -> 61252.15 | G16: =F16+(F16*$B$6) -> 65539.8 | H16: =G16+(G16*$B$6) -> 70127.587 | I16: =H16+(H16*$B$6) -> 75036.518 | J16: =I16+(I16*$B$6) -> 80289.074 | K16: =J16+(J16*$B$6) -> 85909.309 | L16: =K16+(K16*$B$6) -> 91922.961
A17: Gastos administrativos | C17: 200000 | D17: =C17+(C17*$B$6) -> 214000 | E17: =D17+(D17*$B$6) -> 228980 | F17: =E17+(E17*$B$6) -> 245008.6 | G17: =F17+(F17*$B$6) -> 262159.2 | H17: =G17+(G17*$B$6) -> 280510.35 | I17: =H17+(H17*$B$6) -> 300146.07 | J17: =I17+(I17*$B$6) -> 321156.3 | K17: =J17+(J17*$B$6) -> 343637.24 | L17: =K17+(K17*$B$6) -> 367691.84
A19: Valor residual del terreno | B19: 1250000
A20: Valor residual de estanques y canales | B20: 1000000
A21: Valor residual de edificios | B21: 50000
A22: Tasa de fiananciamiento bancario | B22: 0.1
A23: Plazo del financiamiento bancario (años) | B23: 7
A24: Plazo del financiamiento bancario (valor) | B24: =5400000*0.5 -> 2700000
A25: Tasa de corte | B25: 0.19
A26: Tasa de ISR | B26: 0.3
A28: 1. Ingresos del proyecto
A29: Calendario de ingresos (venta del producto)
A30: Concepto | B30: Año 0 | C30: Año 1 | D30: Año 2 | E30: Año 3 | F30: Año 4 | G30: Año 5 | H30: Año 6 | I30: Año 7 | J30: Año 8 | K30: Año 9 | L30: Año 10
A31: Cantidad de camarón (Lb) | C31: =C10 -> 918750 | D31: =D10 -> 1323000 | E31: =E10 -> 1543500 | F31: =F10 -> 1764000 | G31: =G10 -> 1984500 | H31: =H10 -> 1984500 | I31: =I10 -> 1984500 | J31: =J10 -> 1984500 | ... L31: =L10 -> 1984500
A32: Precio unitario de venta ($/Lb) | C32: =C12 -> 3 | D32: =D12 -> 3.21 | E32: =E12 -> 3.4347 | F32: =F12 -> 3.675129 | G32: =G12 -> 3.932388 | H32: =H12 -> 4.2076552 | I32: =I12 -> 4.5021911 | J32: =J12 -> 4.8173444 | ... L32: =L12 -> 5.5153776
A33: Ingresos | C33: =C32*C31 -> 2756250 | D33: =D32*D31 -> 4246830 | E33: =E32*E31 -> 5301459.5 | F33: =F32*F31 -> 6482927.6 | G33: =G32*G31 -> 7803824 | H33: =H32*H31 -> 8350091.7 | I33: =I32*I31 -> 8934598.1 | J33: =J32*J31 -> 9560020 | ... L33: =L32*L31 -> 10945267
A35: 2. Costos variables
A36: Calendario de costos variables
A37: Concepto | B37: Año 0 | C37: Año 1 | D37: Año 2 | E37: Año 3 | F37: Año 4 | G37: Año 5 | H37: Año 6 | I37: Año 7 | J37: Año 8 | K37: Año 9 | L37: Año 10
A38: Costos variables | C38: =C15 -> 1332187.5 | D38: =D15 -> 2052634.5 | E38: =E15 -> 2562372.1 | F38: =F15 -> 3133415 | G38: =G15 -> 3771848.3 | H38: =H15 -> 4035877.7 | I38: =I15 -> 4318389.1 | J38: =J15 -> 4620676.3 | ... L38: =L15 -> 5290212.3
A39: Total de costos variables | C39: =C38 -> 1332187.5 | D39: =D38 -> 2052634.5 | E39: =E38 -> 2562372.1 | F39: =F38 -> 3133415 | G39: =G38 -> 3771848.3 | H39: =H38 -> 4035877.7 | I39: =I38 -> 4318389.1 | J39: =J38 -> 4620676.3 | ... L39: =L38 -> 5290212.3
A41: 3. Costos fijos
A42: Calendario de los costos fijos
A43: Concepto | B43: Año 0 | C43: Año 1 | D43: Año 2 | E43: Año 3 | F43: Año 4 | G43: Año 5 | H43: Año 6 | I43: Año 7 | J43: Año 8 | K43: Año 9 | L43: Año 10
A44: Costos fijos de producción | C44: =C16 -> 50000 | D44: =D16 -> 53500 | E44: =E16 -> 57245 | F44: =F16 -> 61252.15 | G44: =G16 -> 65539.8 | H44: =H16 -> 70127.587 | I44: =I16 -> 75036.518 | J44: =J16 -> 80289.074 | ... L44: =L16 -> 91922.961
A45: Gastos administrativos | C45: =C17 -> 200000 | D45: =D17 -> 214000 | E45: =E17 -> 228980 | F45: =F17 -> 245008.6 | G45: =G17 -> 262159.2 | H45: =H17 -> 280510.35 | I45: =I17 -> 300146.07 | J45: =J17 -> 321156.3 | ... L45: =L17 -> 367691.84
...

Sheet Italiano
A1: Camaronera Industrial
A3: Variables
A4: Horizonte de evaluación (años) | B4: 10
A5: Devaluación | B5: 0.05
A6: Inflación | B6: 0.07
B7: Año 0 | C7: Año 1 | D7: Año 2 | E7: Año 3 | F7: Año 4 | G7: Año 5 | H7: Año 6 | I7: Año 7 | J7: Año 8 | K7: Año 9 | L7: Año 10
A8: Área en producción (Ha) | C8: 750 | D8: 900 | E8: 900 | F8: 900 | G8: 900 | H8: 900 | I8: 900 | J8: 900 | K8: 900 | L8: 900
A9: Producción neta (Lb/Ha/año) | C9: =1225 -> 1225 | D9: =1470 -> 1470 | E9: =1715 -> 1715 | F9: =1960 -> 1960 | G9: =2205 -> 2205 | H9: =2205 -> 2205 | I9: =2205 -> 2205 | J9: =2205 -> 2205 | K9: =2205 -> 2205 | L9: =2205 -> 2205
A10: Producción neta total (Lb/año) | C10: =C9*C8 -> 918750 | D10: =D9*D8 -> 1323000 | E10: =E9*E8 -> 1543500 | F10: =F9*F8 -> 1764000 | G10: =G9*G8 -> 1984500 | H10: =H9*H8 -> 1984500 | I10: =I9*I8 -> 1984500 | J10: =J9*J8 -> 1984500 | ... L10: =L9*L8 -> 1984500
A11: Tasa de cambio | C11: 1 | D11: =C11+(C11*$B$5) -> 1.05 | E11: =D11+(D11*$B$5) -> 1.1025 | F11: =E11+(E11*$B$5) -> 1.157625 | G11: =F11+(F11*$B$5) -> 1.2155063 | H11: =G11+(G11*$B$5) -> 1.2762816 | I11: =H11+(H11*$B$5) -> 1.3400956 | J11: =I11+(I11*$B$5) -> 1.4071004 | K11: =J11+(J11*$B$5) -> 1.4774554 | L11: =K11+(K11*$B$5) -> 1.5513282
A12: Precio de venta FOB ($/Lb) | C12: 3 | D12: =C12+(C12*$B$6) -> 3.21 | E12: =D12+(D12*$B$6) -> 3.4347 | F12: =E12+(E12*$B$6) -> 3.675129 | G12: =F12+(F12*$B$6) -> 3.932388 | H12: =G12+(G12*$B$6) -> 4.2076552 | I12: =H12+(H12*$B$6) -> 4.5021911 | J12: =I12+(I12*$B$6) -> 4.8173444 | K12: =J12+(J12*$B$6) -> 5.1545585 | L12: =K12+(K12*$B$6) -> 5.5153776
A13: Capital de trabajo | C13: 450000 | D13: 250000 | E13: 250000 | F13: 250000 | G13: 250000 | H13: 250000 | I13: 0 | J13: 0 | K13: 0 | L13: 0
A14: Costos variables ($1.45 x Lb) | C14: =1.45 -> 1.45 | D14: =C14+(C14*$B$6) -> 1.5515 | E14: =D14+(D14*$B$6) -> 1.660105 | F14: =E14+(E14*$B$6) -> 1.7763123 | G14: =F14+(F14*$B$6) -> 1.9006542 | H14: =G14+(G14*$B$6) -> 2.0337 | I14: =H14+(H14*$B$6) -> 2.176059 | J14: =I14+(I14*$B$6) -> 2.3283831 | K14: =J14+(J14*$B$6) -> 2.49137 | L14: =K14+(K14*$B$6) -> 2.6657659
A15: Costos variables anuales | C15: =C14*C10 -> 1332187.5 | D15: =D14*D10 -> 2052634.5 | E15: =E14*E10 -> 2562372.1 | F15: =F14*F10 -> 3133415 | G15: =G14*G10 -> 3771848.3 | H15: =H14*H10 -> 4035877.7 | I15: =I14*I10 -> 4318389.1 | J15: =J14*J10 -> 4620676.3 | ... L15: =L14*L10 -> 5290212.3
A16: Costos fijos de producción | C16: 50000 | D16: =C16+(C16*$B$6) -> 53500 | E16: =D16+(D16*$B$6) -> 57245 | F16: =E16+(E16*$B$6) -> 61252.15 | G16: =F16+(F16*$B$6) -> 65539.8 | H16: =G16+(G16*$B$6) -> 70127.587 | I16: =H16+(H16*$B$6) -> 75036.518 | J16: =I16+(I16*$B$6) -> 80289.074 | K16: =J16+(J16*$B$6) -> 85909.309 | L16: =K16+(K16*$B$6) -> 91922.961
A17: Gastos administrativos | C17: 200000 | D17: =C17+(C17*$B$6) -> 214000 | E17: =D17+(D17*$B$6) -> 228980 | F17: =E17+(E17*$B$6) -> 245008.6 | G17: =F17+(F17*$B$6) -> 262159.2 | H17: =G17+(G17*$B$6) -> 280510.35 | I17: =H17+(H17*$B$6) -> 300146.07 | J17: =I17+(I17*$B$6) -> 321156.3 | K17: =J17+(J17*$B$6) -> 343637.24 | L17: =K17+(K17*$B$6) -> 367691.84
A19: Valor residual del terreno | B19: 1250000
A20: Valor residual de estanques y canales | B20: 1000000
A21: Valor residual de edificios | B21: 50000
A22: Tasa de fiananciamiento bancario | B22: 0.1
A23: Plazo del financiamiento bancario (años) | B23: 7
A24: Plazo del financiamiento bancario (valor) | B24: =5400000*0.5 -> 2700000
A25: Tasa de corte | B25: 0.19
A26: Tasa de ISR | B26: 0.3
A28: 1. Ingresos del proyecto
A29: Calendario de ingresos (venta del producto)
A30: Concepto | B30: Año 0 | C30: Año 1 | D30: Año 2 | E30: Año 3 | F30: Año 4 | G30: Año 5 | H30: Año 6 | I30: Año 7 | J30: Año 8 | K30: Año 9 | L30: Año 10
A31: Cantidad de camarón (Lb) | C31: =C10 -> 918750 | D31: =D10 -> 1323000 | E31: =E10 -> 1543500 | F31: =F10 -> 1764000 | G31: =G10 -> 1984500 | H31: =H10 -> 1984500 | I31: =I10 -> 1984500 | J31: =J10 -> 1984500 | ... L31: =L10 -> 1984500
A32: Precio unitario de venta ($/Lb) | C32: =C12 -> 3 | D32: =D12 -> 3.21 | E32: =E12 -> 3.4347 | F32: =F12 -> 3.675129 | G32: =G12 -> 3.932388 | H32: =H12 -> 4.2076552 | I32: =I12 -> 4.5021911 | J32: =J12 -> 4.8173444 | ... L32: =L12 -> 5.5153776
A33: Ingresos | C33: =C32*C31 -> 2756250 | D33: =D32*D31 -> 4246830 | E33: =E32*E31 -> 5301459.5 | F33: =F32*F31 -> 6482927.6 | G33: =G32*G31 -> 7803824 | H33: =H32*H31 -> 8350091.7 | I33: =I32*I31 -> 8934598.1 | J33: =J32*J31 -> 9560020 | ... L33: =L32*L31 -> 10945267
A35: 2. Costos variables
A36: Calendario de costos variables
A37: Concepto | B37: Año 0 | C37: Año 1 | D37: Año 2 | E37: Año 3 | F37: Año 4 | G37: Año 5 | H37: Año 6 | I37: Año 7 | J37: Año 8 | K37: Año 9 | L37: Año 10
A38: Costos variables | C38: =C15 -> 1332187.5 | D38: =D15 -> 2052634.5 | E38: =E15 -> 2562372.1 | F38: =F15 -> 3133415 | G38: =G15 -> 3771848.3 | H38: =H15 -> 4035877.7 | I38: =I15 -> 4318389.1 | J38: =J15 -> 4620676.3 | ... L38: =L15 -> 5290212.3
A39: Total de costos variables | C39: =C38 -> 1332187.5 | D39: =D38 -> 2052634.5 | E39: =E38 -> 2562372.1 | F39: =F38 -> 3133415 | G39: =G38 -> 3771848.3 | H39: =H38 -> 4035877.7 | I39: =I38 -> 4318389.1 | J39: =J38 -> 4620676.3 | ... L39: =L38 -> 5290212.3
A41: 3. Costos fijos
A42: Calendario de los costos fijos
A43: Concepto | B43: Año 0 | C43: Año 1 | D43: Año 2 | E43: Año 3 | F43: Año 4 | G43: Año 5 | H43: Año 6 | I43: Año 7 | J43: Año 8 | K43: Año 9 | L43: Año 10
A44: Costos fijos de producción | C44: =C16 -> 50000 | D44: =D16 -> 53500 | E44: =E16 -> 57245 | F44: =F16 -> 61252.15 | G44: =G16 -> 65539.8 | H44: =H16 -> 70127.587 | I44: =I16 -> 75036.518 | J44: =J16 -> 80289.074 | ... L44: =L16 -> 91922.961
A45: Gastos administrativos | C45: =C17 -> 200000 | D45: =D17 -> 214000 | E45: =E17 -> 228980 | F45: =F17 -> 245008.6 | G45: =G17 -> 262159.2 | H45: =H17 -> 280510.35 | I45: =I17 -> 300146.07 | J45: =J17 -> 321156.3 | ... L45: =L17 -> 367691.84
...

Sheet Alemán
A1: Camaronera Industrial
A3: Variables
A4: Horizonte de evaluación (años) | B4: 10
A5: Devaluación | B5: 0.05
A6: Inflación | B6: 0.07
B7: Año 0 | C7: Año 1 | D7: Año 2 | E7: Año 3 | F7: Año 4 | G7: Año 5 | H7: Año 6 | I7: Año 7 | J7: Año 8 | K7: Año 9 | L7: Año 10
A8: Área en producción (Ha) | C8: 750 | D8: 900 | E8: 900 | F8: 900 | G8: 900 | H8: 900 | I8: 900 | J8: 900 | K8: 900 | L8: 900
A9: Producción neta (Lb/Ha/año) | C9: =1225 -> 1225 | D9: =1470 -> 1470 | E9: =1715 -> 1715 | F9: =1960 -> 1960 | G9: =2205 -> 2205 | H9: =2205 -> 2205 | I9: =2205 -> 2205 | J9: =2205 -> 2205 | K9: =2205 -> 2205 | L9: =2205 -> 2205
A10: Producción neta total (Lb/año) | C10: =C9*C8 -> 918750 | D10: =D9*D8 -> 1323000 | E10: =E9*E8 -> 1543500 | F10: =F9*F8 -> 1764000 | G10: =G9*G8 -> 1984500 | H10: =H9*H8 -> 1984500 | I10: =I9*I8 -> 1984500 | J10: =J9*J8 -> 1984500 | ... L10: =L9*L8 -> 1984500
A11: Tasa de cambio | C11: 1 | D11: =C11+(C11*$B$5) -> 1.05 | E11: =D11+(D11*$B$5) -> 1.1025 | F11: =E11+(E11*$B$5) -> 1.157625 | G11: =F11+(F11*$B$5) -> 1.2155063 | H11: =G11+(G11*$B$5) -> 1.2762816 | I11: =H11+(H11*$B$5) -> 1.3400956 | J11: =I11+(I11*$B$5) -> 1.4071004 | K11: =J11+(J11*$B$5) -> 1.4774554 | L11: =K11+(K11*$B$5) -> 1.5513282
A12: Precio de venta FOB ($/Lb) | C12: 3 | D12: =C12+(C12*$B$6) -> 3.21 | E12: =D12+(D12*$B$6) -> 3.4347 | F12: =E12+(E12*$B$6) -> 3.675129 | G12: =F12+(F12*$B$6) -> 3.932388 | H12: =G12+(G12*$B$6) -> 4.2076552 | I12: =H12+(H12*$B$6) -> 4.5021911 | J12: =I12+(I12*$B$6) -> 4.8173444 | K12: =J12+(J12*$B$6) -> 5.1545585 | L12: =K12+(K12*$B$6) -> 5.5153776
A13: Capital de trabajo | C13: 450000 | D13: 250000 | E13: 250000 | F13: 250000 | G13: 250000 | H13: 250000 | I13: 0 | J13: 0 | K13: 0 | L13: 0
A14: Costos variables ($1.45 x Lb) | C14: =1.45 -> 1.45 | D14: =C14+(C14*$B$6) -> 1.5515 | E14: =D14+(D14*$B$6) -> 1.660105 | F14: =E14+(E14*$B$6) -> 1.7763123 | G14: =F14+(F14*$B$6) -> 1.9006542 | H14: =G14+(G14*$B$6) -> 2.0337 | I14: =H14+(H14*$B$6) -> 2.176059 | J14: =I14+(I14*$B$6) -> 2.3283831 | K14: =J14+(J14*$B$6) -> 2.49137 | L14: =K14+(K14*$B$6) -> 2.6657659
A15: Costos variables anuales | C15: =C14*C10 -> 1332187.5 | D15: =D14*D10 -> 2052634.5 | E15: =E14*E10 -> 2562372.1 | F15: =F14*F10 -> 3133415 | G15: =G14*G10 -> 3771848.3 | H15: =H14*H10 -> 4035877.7 | I15: =I14*I10 -> 4318389.1 | J15: =J14*J10 -> 4620676.3 | ... L15: =L14*L10 -> 5290212.3
A16: Costos fijos de producción | C16: 50000 | D16: =C16+(C16*$B$6) -> 53500 | E16: =D16+(D16*$B$6) -> 57245 | F16: =E16+(E16*$B$6) -> 61252.15 | G16: =F16+(F16*$B$6) -> 65539.8 | H16: =G16+(G16*$B$6) -> 70127.587 | I16: =H16+(H16*$B$6) -> 75036.518 | J16: =I16+(I16*$B$6) -> 80289.074 | K16: =J16+(J16*$B$6) -> 85909.309 | L16: =K16+(K16*$B$6) -> 91922.961
A17: Gastos administrativos | C17: 200000 | D17: =C17+(C17*$B$6) -> 214000 | E17: =D17+(D17*$B$6) -> 228980 | F17: =E17+(E17*$B$6) -> 245008.6 | G17: =F17+(F17*$B$6) -> 262159.2 | H17: =G17+(G17*$B$6) -> 280510.35 | I17: =H17+(H17*$B$6) -> 300146.07 | J17: =I17+(I17*$B$6) -> 321156.3 | K17: =J17+(J17*$B$6) -> 343637.24 | L17: =K17+(K17*$B$6) -> 367691.84
A19: Valor residual del terreno | B19: 1250000
A20: Valor residual de estanques y canales | B20: 1000000
A21: Valor residual de edificios | B21: 50000
A22: Tasa de fiananciamiento bancario | B22: 0.1
A23: Plazo del financiamiento bancario (años) | B23: 7
A24: Plazo del financiamiento bancario (valor) | B24: =5400000*0.5 -> 2700000
A25: Tasa de corte | B25: 0.19
A26: Tasa de ISR | B26: 0.3
A28: 1. Ingresos del proyecto
A29: Calendario de ingresos (venta del producto)
A30: Concepto | B30: Año 0 | C30: Año 1 | D30: Año 2 | E30: Año 3 | F30: Año 4 | G30: Año 5 | H30: Año 6 | I30: Año 7 | J30: Año 8 | K30: Año 9 | L30: Año 10
A31: Cantidad de camarón (Lb) | C31: =C10 -> 918750 | D31: =D10 -> 1323000 | E31: =E10 -> 1543500 | F31: =F10 -> 1764000 | G31: =G10 -> 1984500 | H31: =H10 -> 1984500 | I31: =I10 -> 1984500 | J31: =J10 -> 1984500 | ... L31: =L10 -> 1984500
A32: Precio unitario de venta ($/Lb) | C32: =C12 -> 3 | D32: =D12 -> 3.21 | E32: =E12 -> 3.4347 | F32: =F12 -> 3.675129 | G32: =G12 -> 3.932388 | H32: =H12 -> 4.2076552 | I32: =I12 -> 4.5021911 | J32: =J12 -> 4.8173444 | ... L32: =L12 -> 5.5153776
A33: Ingresos | C33: =C32*C31 -> 2756250 | D33: =D32*D31 -> 4246830 | E33: =E32*E31 -> 5301459.5 | F33: =F32*F31 -> 6482927.6 | G33: =G32*G31 -> 7803824 | H33: =H32*H31 -> 8350091.7 | I33: =I32*I31 -> 8934598.1 | J33: =J32*J31 -> 9560020 | ... L33: =L32*L31 -> 10945267
A35: 2. Costos variables
A36: Calendario de costos variables
A37: Concepto | B37: Año 0 | C37: Año 1 | D37: Año 2 | E37: Año 3 | F37: Año 4 | G37: Año 5 | H37: Año 6 | I37: Año 7 | J37: Año 8 | K37: Año 9 | L37: Año 10
A38: Costos variables | C38: =C15 -> 1332187.5 | D38: =D15 -> 2052634.5 | E38: =E15 -> 2562372.1 | F38: =F15 -> 3133415 | G38: =G15 -> 3771848.3 | H38: =H15 -> 4035877.7 | I38: =I15 -> 4318389.1 | J38: =J15 -> 4620676.3 | ... L38: =L15 -> 5290212.3
A39: Total de costos variables | C39: =C38 -> 1332187.5 | D39: =D38 -> 2052634.5 | E39: =E38 -> 2562372.1 | F39: =F38 -> 3133415 | G39: =G38 -> 3771848.3 | H39: =H38 -> 4035877.7 | I39: =I38 -> 4318389.1 | J39: =J38 -> 4620676.3 | ... L39: =L38 -> 5290212.3
A41: 3. Costos fijos
A42: Calendario de los costos fijos
A43: Concepto | B43: Año 0 | C43: Año 1 | D43: Año 2 | E43: Año 3 | F43: Año 4 | G43: Año 5 | H43: Año 6 | I43: Año 7 | J43: Año 8 | K43: Año 9 | L43: Año 10
A44: Costos fijos de producción | C44: =C16 -> 50000 | D44: =D16 -> 53500 | E44: =E16 -> 57245 | F44: =F16 -> 61252.15 | G44: =G16 -> 65539.8 | H44: =H16 -> 70127.587 | I44: =I16 -> 75036.518 | J44: =J16 -> 80289.074 | ... L44: =L16 -> 91922.961
A45: Gastos administrativos | C45: =C17 -> 200000 | D45: =D17 -> 214000 | E45: =E17 -> 228980 | F45: =F17 -> 245008.6 | G45: =G17 -> 262159.2 | H45: =H17 -> 280510.35 | I45: =I17 -> 300146.07 | J45: =J17 -> 321156.3 | ... L45: =L17 -> 367691.84
...
